Workbook

Sheet СТА за марта 2026 года
A8: Настоящий Акт составлен по серии Локомотивов | F8: 2ЭС6
A10: № п/п | B10: Номер Локомотива | C10: Фактический пробег локомотива за период * | D10: Пробег локомотивов, подлежащий оплате * | E10: Количество часов нахождения локомотива в эксплуатации** | F10: Дата постановки Локомотива в ремонт | G10: Время постановки Локомотива в ремонт | H10: № Акта приемки Локомотива в ремонт | I10: Вид ремонта | J10: Дата выхода Локомотива из ремонта | K10: Время выхода Локомотива из ремонта | L10: № Акта приемки Локомотива из ремонта | M10: Количество часов нахождения Локомотива в ремонте* | P10: Дата постановки в ОЖ. ТО-2, ОЖ. ТО-2 с экипировкой,ож ТР, ож НЕПЛ РЕМ | Q10: Время в ОЖ. | R10: Время в ОЖ. За вычетом 1 часа в ИСПРАВНОМ состоянии
A11: 1 | B11: 730 | F11: 05-03-26 08:31 | G11: =RIGHT(F11,5) -> 08:31 | H11: №495 | I11: ТО-2 | J11: 05-03-26 09:42 | K11: =RIGHT(J11,5) -> 09:42 | L11: =H11 -> №495 | M11: =(J11-F11)*24 -> 1.1833333 | N11: Эксплуатация | O11: =SUMIF(A:A,"*в работоспособном состоянии*",E:E) -> 3655.5 | P11: 05-03-26 05:32 | Q11: =(F11-P11)*24 -> 2.9833333 | R11: =Q11-1 -> 1.9833333
A12: 2 | B12: 730 | F12: 14-03-26 04:55 | G12: =RIGHT(F12,5) -> 04:55 | H12: №557 | I12: ТО-2 | J12: 14-03-26 06:14 | K12: =RIGHT(J12,5) -> 06:14 | L12: =H12 -> №557 | M12: =(J12-F12)*24 -> 1.3166667 | N12: Пробег | O12: =SUMIF(A:A,"*ВСЕГО*",C:C) -> 75141 | P12: 14-03-26 00:56 | Q12: =(F12-P12)*24 -> 3.9833333 | R12: =Q12-1 -> 2.9833333
A13: 3 | B13: 730 | F13: 22-03-26 13:48 | G13: =RIGHT(F13,5) -> 13:48 | H13: №29 | I13: НР | J13: 22-03-26 14:12 | K13: =RIGHT(J13,5) -> 14:12 | L13: =H13 -> №29 | M13: =(J13-F13)*24 -> 0.4 | N13: Обслуживание | O13: =SUMIF(A:A,"*в Обслуживании (ТО, ТР)*",E:E) -> 19 | P13: 22-03-26 04:25 | Q13: =(F13-P13)*24 -> 9.3833333 | R13: 0
A14: 4 | B14: 730 | F14: 24-03-26 15:21 | G14: =RIGHT(F14,5) -> 15:21 | H14: №633 | I14: ТО-2 | J14: 24-03-26 16:48 | K14: =RIGHT(J14,5) -> 16:48 | L14: =H14 -> №633 | M14: =(J14-F14)*24 -> 1.45 | N14: НР | O14: =SUMIF(A:A,"*в Обслуживании непредвиденном:*",E:E) -> 0.4 | P14: 24-03-26 06:36 | Q14: =(F14-P14)*24 -> 8.75 | R14: =Q14-1 -> 7.75
A15: ИТОГО по лок-ву | C15: =Пробеги!E20 -> 14425 | D15: =C15 -> 14425 | E15: =DAY(EOMONTH(S70,0))*24-M15-R15 -> 726.93333 | M15: =SUM(M11:M14) -> 4.35 | N15: Рекламация | O15: =SUMIF(A:A,"*в Обслуживании гарантийном*",E:E) -> 0 | Q15: =SUM(Q11:Q14) -> 25.1 | R15: =SUM(R11:R14) -> 12.716667
A16: 1 | B16: 731 | F16: 07-03-26 11:03 | G16: =RIGHT(F16,5) -> 11:03 | H16: №514 | I16: ТО-2 | J16: 07-03-26 12:06 | K16: =RIGHT(J16,5) -> 12:06 | L16: =H16 -> №514 | M16: =(J16-F16)*24 -> 1.05 | N16: Адм.изд. | O16: =SUMIF(A:A,"*в ожидании ТО-2*",E:E)+V53+V51 -> 45.1 | P16: 07-03-26 10:20 | Q16: =(F16-P16)*24 -> 0.71666667 | R16: =Q16-Q16 -> 0
A17: 2 | B17: 731 | F17: 16-03-26 20:49 | G17: =RIGHT(F17,5) -> 20:49 | H17: №577 | I17: ТО-2 | J17: 16-03-26 21:54 | K17: =RIGHT(J17,5) -> 21:54 | L17: =H17 -> №577 | M17: =(J17-F17)*24 -> 1.0833333 | N17: План КГЭ | O17: =#REF! -> #REF! | P17: 16-03-26 19:35 | Q17: =(F17-P17)*24 -> 1.2333333 | R17: =Q17-1 -> 0.23333333
A18: 3 | B18: 731 | F18: 26-03-26 12:36 | G18: =RIGHT(F18,5) -> 12:36 | H18: №650 | I18: ТО-2 | J18: 26-03-26 13:39 | K18: =RIGHT(J18,5) -> 13:39 | L18: =H18 -> №650 | M18: =(J18-F18)*24 -> 1.05 | N18: Адм.изд. РЖД раб | O18: =Q33-R33+V45+V52+V44+V43 -> 26.2 | P18: 26-03-26 10:01 | Q18: =(F18-P18)*24 -> 2.5833333 | R18: =Q18-1 -> 1.5833333
A19: ИТОГО по лок-ву | C19: =Пробеги!E22 -> 15113 | D19: =C19 -> 15113 | E19: =DAY(EOMONTH(S70,0))*24-M19-R19 -> 739 | M19: =SUM(M16:M18) -> 3.1833333 | N19: НР РЖД | O19: =V40+V38+E41 -> 1.2833333 | Q19: =SUM(Q16:Q18) -> 4.5333333 | R19: =SUM(R16:R18) -> 1.8166667
A20: 1 | B20: 732 | F20: 08-03-26 14:27 | G20: =RIGHT(F20,5) -> 14:27 | H20: №523 | I20: ТО-2 | J20: 08-03-26 15:41 | K20: =RIGHT(J20,5) -> 15:41 | L20: =H20 -> №523 | M20: =(J20-F20)*24 -> 1.2333333 | N20: Адм.изд. РЖД | O20: =V58+V59 -> 0 | P20: 08-03-26 09:54 | Q20: =(F20-P20)*24 -> 4.55 | R20: =Q20-1 -> 3.55
A21: 2 | B21: 732 | F21: 18-03-26 14:29 | G21: =RIGHT(F21,5) -> 14:29 | H21: №581 | I21: ТО-2 | J21: 18-03-26 15:08 | K21: =RIGHT(J21,5) -> 15:08 | L21: =H21 -> №581 | M21: =(J21-F21)*24 -> 0.65 | P21: 18-03-26 03:21 | Q21: =(F21-P21)*24 -> 11.133333 | R21: =Q21-1 -> 10.133333
A22: 3 | B22: 732 | F22: 28-03-26 23:45 | G22: =RIGHT(F22,5) -> 23:45 | H22: №665 | I22: ТО-2 | J22: 29-03-26 01:09 | K22: =RIGHT(J22,5) -> 01:09 | L22: =H22 -> №665 | M22: =(J22-F22)*24 -> 1.4 | P22: 28-03-26 23:20 | Q22: =(F22-P22)*24 -> 0.41666667 | R22: =Q22-Q22 -> 0
A23: ИТОГО по лок-ву | C23: =Пробеги!E24 -> 14087 | D23: =C23 -> 14087 | E23: =DAY(EOMONTH(S70,0))*24-M23-R23 -> 727.03333 | M23: =SUM(M20:M22) -> 3.2833333 | Q23: =SUM(Q20:Q22) -> 16.1 | R23: =SUM(R20:R22) -> 13.683333
A24: 1 | B24: 733 | F24: 04-03-26 09:06 | G24: =RIGHT(F24,5) -> 09:06 | H24: №485 | I24: ТО-2 | J24: 04-03-26 10:22 | K24: =RIGHT(J24,5) -> 10:22 | L24: =H24 -> №485 | M24: =(J24-F24)*24 -> 1.2666667 | P24: 04-03-26 05:12 | Q24: =(F24-P24)*24 -> 3.9 | R24: =Q24-1 -> 2.9
A25: 2 | B25: 733 | F25: 11-03-26 21:17 | G25: =RIGHT(F25,5) -> 21:17 | H25: №543 | I25: ТО-2 | J25: 11-03-26 22:31 | K25: =RIGHT(J25,5) -> 22:31 | L25: =H25 -> №543 | M25: =(J25-F25)*24 -> 1.2333333 | P25: 11-03-26 19:34 | Q25: =(F25-P25)*24 -> 1.7166667 | R25: =Q25-1 -> 0.71666667
A26: 3 | B26: 733 | F26: 21-03-26 13:10 | G26: =RIGHT(F26,5) -> 13:10 | H26: №606 | I26: ТО-2 | J26: 21-03-26 14:43 | K26: =RIGHT(J26,5) -> 14:43 | L26: =H26 -> №606 | M26: =(J26-F26)*24 -> 1.55 | P26: 21-03-26 11:38 | Q26: =(F26-P26)*24 -> 1.5333333 | R26: =Q26-1 -> 0.53333333
A27: 4 | B27: 733 | F27: 30-03-26 14:01 | G27: =RIGHT(F27,5) -> 14:01 | H27: №677 | I27: ТО-2 | J27: 30-03-26 15:01 | K27: =RIGHT(J27,5) -> 15:01 | L27: =H27 -> №677 | M27: =(J27-F27)*24 -> 1 | P27: 30-03-26 11:50 | Q27: =(F27-P27)*24 -> 2.1833333 | R27: =Q27-1 -> 1.1833333
A28: ИТОГО по лок-ву | C28: =Пробеги!E26 -> 15888 | D28: =C28 -> 15888 | E28: =DAY(EOMONTH(S70,0))*24-R28-M28 -> 733.61667 | M28: =SUM(M24:M27) -> 5.05 | Q28: =SUM(Q24:Q27) -> 9.3333333 | R28: =SUM(R24:R27) -> 5.3333333
A29: 1 | B29: 734 | F29: 04-03-26 20:53 | G29: =RIGHT(F29,5) -> 20:53 | H29: №491 | I29: ТО-2 | J29: 04-03-26 21:57 | K29: =RIGHT(J29,5) -> 21:57 | L29: =H29 -> №491 | M29: =(J29-F29)*24 -> 1.0666667 | P29: 04-03-26 15:15 | Q29: =(F29-P29)*24 -> 5.6333333 | R29: =Q29-1 -> 4.6333333
A30: 2 | B30: 734 | F30: 13-03-26 14:45 | G30: =RIGHT(F30,5) -> 14:45 | H30: №554 | I30: ТО-2 | J30: 13-03-26 15:57 | K30: =RIGHT(J30,5) -> 15:57 | L30: =H30 -> №554 | M30: =(J30-F30)*24 -> 1.2 | P30: 13-03-26 10:34 | Q30: =(F30-P30)*24 -> 4.1833333 | R30: =Q30-1 -> 3.1833333
A31: 3 | B31: 734 | F31: 23-03-26 20:24 | G31: =RIGHT(F31,5) -> 20:24 | H31: №625 | I31: ТО-2 | J31: 23-03-26 21:40 | K31: =RIGHT(J31,5) -> 21:40 | L31: =H31 -> №625 | M31: =(J31-F31)*24 -> 1.2666667 | P31: 23-03-26 15:40 | Q31: =(F31-P31)*24 -> 4.7333333 | R31: =Q31-1 -> 3.7333333
A32: ИТОГО по лок-ву | C32: =Пробеги!E28 -> 15628 | D32: =C32 -> 15628 | E32: =DAY(EOMONTH(S70,0))*24-M32-R32 -> 728.91667 | M32: =SUM(M29:M31) -> 3.5333333 | Q32: =SUM(Q29:Q31) -> 14.55 | R32: =SUM(R29:R31) -> 11.55
A33: ВСЕГО | C33: =C15+C19+C23+C28+C32 -> 75141 | D33: =D15+D19+D23+D28+D32 -> 75141 | E33: =E15+E19+E23+E28+E32 -> 3655.5 | M33: =M32+M28+M23+M19+M15 -> 19.4 | Q33: =SUM(Q15,Q19,Q23,Q28,Q32) -> 69.616667 | R33: =R15+R19+R23+R28+R32 -> 45.1
A34: * - пробеги локомотива заполняются только в итоговой строке по этому локомотиву
A35: ** - с учётом времени простоев на станционных или деповских путях в ожидании технического обслуживания ТО-2, ТО-2 и экипировки, ТР.
P36: Неплановый ремонт по вине ОАО "РЖД". Выдержка из истории локомотива АСУТЦТ
A37: Примечание: Пробег локомотивов, подлежащий оплате, рассчитывается по формуле, приведенной в пункте 19.1 Договора. | P37: Серия | Q37: Номер | R37: Дата | S37: Состояние | T37: Операция | U37: Дислокация | V37: время
P38: 2ЭС6 | Q38: 731 | R38: 05-03-26 01:30 | S38: НР | T38: 05-03-26 02:23 | U38: РЦ-15 БАБАЕВО | V38: =(T38-R38)*24 -> 0.88333333
A39: Количество часов нахождения в работоспособном состоянии: | E39: =E33 -> 3655.5
A40: Количество часов нахождения в Обслуживании (ТО, ТР): | E40: =M33-M13 -> 19
A41: Количество часов нахождения в Обслуживании непредвиденном: | E41: =M13 -> 0.4
A42: Количество часов нахождения в Обслуживании гарантийном: | E42: 0 | P42: ОЖ.НР / ОЖ.ОТПР.НР.
A43: Количество часов нахождения в ожидании ТО-2, ТО-2 с экипировкой, ТР: | E43: =R33 -> 45.1 | P43: 2ЭС6 | Q43: 731 | R43: 04-03-26 23:48 | S43: ОЖ.НР. | T43: 05-03-26 01:29 | U43: РЦ-15 БАБАЕВО | V43: =(T43-R43)*24 -> 1.6833333
A44: КТГф составил: | E44: =(E39)/(E39+E40+E42+E43) -> 0.98276696
P46: Неплановый ремонт по вине ООО "УЛ". Выдержка из истории локомотива АСУТЦТ
P49: Время из работоспособного состояния
S70: =DATE(2026, 3,1) -> 46082 | U70: =DATE(2026,1,1) -> 46023 | V70: января
U71: =DATE(2026,2,1) -> 46054 | V71: февраля
...

Sheet Пробеги
A1: Отчёт по пробегам секций локомотивов, времени пребывания локомотивов в эксплуатируемом и неэксплуатируемом парках
A2: Дата и время выдачи справки: 2026-04-01 05.06
A3: Начало интервала: 2026-02-28 18.00.00
A4: Окончание интервала: 2026-03-31 18.00.00
A5: Дирекция тяги приписки: Октябрьская
A6: Депо приписки: ТЧЭ-21 ВОЛХОВСТРОЙ
A7: Вид тяги: электровозы
A8: Род службы ТПС: все
A9: Группа серий ТПС: все
A10: Серия локомотивов: 2ЭС6
A11: Номер секции: все
A12: Признак секции: все
A14: Отчёт по пробегам локомотивов
A15: Дирекция | B15: Депо | C15: Серия | D15: Номер | E15: Фактический | G15: Фактическое время в | K15: Фактическое время в
A16: тяги | B16: приписки | C16: локомотива | D16: секции | E16: пробег | G16: эксплуатируемом парке, ч | K16: неэксплуатируемом парке, ч
A17: приписки | B17: локомотива | E17: км | F17: ч | G17: Итого | H17: В том числе в | I17: В том числе в | J17: В том числе в ожидании ТО-2, на ТО-2 и экипировке | K17: Итого | L17: В том числе на | M17: В том числе на
H18: рабочем парке | I18: ожидании работы | L18: плановых ТО, ТР | M18: неплановых ремонтах
A19: 1 | B19: 2 | C19: 3 | D19: 4 | E19: 5 | F19: 6 | G19: 7 | H19: 8 | I19: 9 | J19: 10 | K19: 11 | L19: 12 | M19: 13
A20: Октябрьская | B20: ТЧЭ-21 ВОЛХОВСТРОЙ | C20: 2ЭС6 | D20: 0730 A | E20: 14425 | F20: 734 | G20: 734 | H20: 494 | I20: 76 | J20: 19 | K20: 10 | L20: 0 | M20: 10
A21: Октябрьская | B21: ТЧЭ-21 ВОЛХОВСТРОЙ | C21: 2ЭС6 | D21: 0730 Б | E21: 14425 | F21: 734 | G21: 734 | H21: 494 | I21: 76 | J21: 19 | K21: 10 | L21: 0 | M21: 10
A22: Октябрьская | B22: ТЧЭ-21 ВОЛХОВСТРОЙ | C22: 2ЭС6 | D22: 0731 A | E22: 15113 | F22: 741 | G22: 741 | H22: 485 | I22: 85 | J22: 8 | K22: 3 | L22: 0 | M22: 3
A23: Октябрьская | B23: ТЧЭ-21 ВОЛХОВСТРОЙ | C23: 2ЭС6 | D23: 0731 Б | E23: 15113 | F23: 741 | G23: 741 | H23: 485 | I23: 85 | J23: 8 | K23: 3 | L23: 0 | M23: 3
A24: Октябрьская | B24: ТЧЭ-21 ВОЛХОВСТРОЙ | C24: 2ЭС6 | D24: 0732 A | E24: 14087 | F24: 744 | G24: 744 | H24: 448 | I24: 116 | J24: 20 | K24: 0 | L24: 0 | M24: 0
A25: Октябрьская | B25: ТЧЭ-21 ВОЛХОВСТРОЙ | C25: 2ЭС6 | D25: 0732 Б | E25: 14087 | F25: 744 | G25: 744 | H25: 448 | I25: 116 | J25: 20 | K25: 0 | L25: 0 | M25: 0
A26: Октябрьская | B26: ТЧЭ-21 ВОЛХОВСТРОЙ | C26: 2ЭС6 | D26: 0733 A | E26: 15888 | F26: 744 | G26: 744 | H26: 511 | I26: 74 | J26: 14 | K26: 0 | L26: 0 | M26: 0
A27: Октябрьская | B27: ТЧЭ-21 ВОЛХОВСТРОЙ | C27: 2ЭС6 | D27: 0733 Б | E27: 15888 | F27: 744 | G27: 744 | H27: 511 | I27: 74 | J27: 14 | K27: 0 | L27: 0 | M27: 0
A28: Октябрьская | B28: ТЧЭ-21 ВОЛХОВСТРОЙ | C28: 2ЭС6 | D28: 0734 A | E28: 15628 | F28: 744 | G28: 744 | H28: 506 | I28: 95 | J28: 18 | K28: 0 | L28: 0 | M28: 0
A29: Октябрьская | B29: ТЧЭ-21 ВОЛХОВСТРОЙ | C29: 2ЭС6 | D29: 0734 Б | E29: 15628 | F29: 744 | G29: 744 | H29: 506 | I29: 95 | J29: 18 | K29: 0 | L29: 0 | M29: 0
E30: =SUM(E20:E29)/2 -> 75141
E31: =E30/31/5 -> 484.78065
