Workbook
Name _Toc410296219: 'СТА за март 2026 года (2ЭС7)'!$A$78
Name _Toc410296220: 'СТА за март 2026 года (2ЭС7)'!$A$82
Name _Toc410296221: 'СТА за март 2026 года (2ЭС7)'!$A$85
Name _Toc410296222: 'СТА за март 2026 года (2ЭС7)'!$A$87

Sheet СТА за март 2026 года (2ЭС7)
A11: Настоящий Акт составлен по серии Локомотивов | H11: 2ЭС7
A13: № п/п | B13: Серия локомотива | C13: Номер Локомотива | D13: Кол-во секций | E13: Фактический пробег (часы в эксплуатации) всех секций локомотива без превышения межремонтного периода км/час | F13: Фактический пробег (часы в эксплуатации) всех секций локомотива с превышением межремонтного периода км/час | G13: Фактический пробег (часы в эксплуатации) всех секций локомотива с превышением межремонтного периода, допущенный по вине Исполнителя км/час | H13: Фактический пробег (часы в эксплуатации) всех секций локомотива за месяц, подлежащий оплате км/час | I13: Дата постановки Локомотива в ремонт | J13: Время постановки Локомотива в ремонт | K13: № Акта приемки Локомотива в ремонт | L13: Вид ремонта | M13: Дата выхода Локомотива из ремонта | N13: Время выхода Локомотива из ремонта | O13: № Акта приемки Локомотива из ремонта | P13: Кол-во часов нахождения в ремонте одной секции | Q13: Количество часов нахождения всех секций в ремонте (суммарно) | T13: Дата постановки в ОЖ. ТО-2, ОЖ. ТО-2 с экипировкой,ож ТР,ож НЕПЛ РЕМ | U13: Время в ОЖ. | V13: Время в ОЖ. За вычетом 1 часа в ИСПРАВНОМ состоянии
A14: 1 | B14: 2ЭС7 | C14: 001 | D14: 2 | I14: 01-03-26 01:16 | J14: =RIGHT(I14,5) -> 01:16 | K14: №464 | L14: ТО-2 | M14: 01-03-26 03:19 | N14: =RIGHT(M14,5) -> 03:19 | O14: =K14 -> №464 | P14: =(M14-I14)*24 -> 2.05 | Q14: =P14*2 -> 4.1 | R14: Эксплуатация | S14: =SUMIF(A:A,"*нахождения в эксплуатации*",G:G) -> 18001.8 | T14: 28-02-26 16:45 | U14: =(I14-T14)*24 -> 8.5166667 | V14: =IF(U14<=1,0,U14-U14) -> 0
A15: 2 | B15: 2ЭС7 | C15: 001 | D15: 2 | I15: 12-03-26 16:08 | J15: =RIGHT(I15,5) -> 16:08 | K15: №231 | L15: НР | M15: 12-03-26 18:04 | N15: =RIGHT(M15,5) -> 18:04 | O15: =K15 -> №231 | P15: =(M15-I15)*24 -> 1.9333333 | Q15: =P15*2 -> 3.8666667 | R15: Пробег | S15: =SUMIF(A:A,"*км.пробега*",G:G) -> 492026 | T15: 11-03-26 23:28 | U15: =(I15-T15)*24 -> 16.666667 | V15: =U15 -> 16.666667
A16: 3 | B16: 2ЭС7 | C16: 001 | D16: 2 | I16: 22-03-26 16:46 | J16: =RIGHT(I16,5) -> 16:46 | K16: №616 | L16: ТО-2 | M16: 22-03-26 18:50 | N16: =RIGHT(M16,5) -> 18:50 | O16: =K16 -> №616 | P16: =(M16-I16)*24 -> 2.0666667 | Q16: =P16*2 -> 4.1333333 | R16: Обслуживание | S16: =SUMIF(A:A,"*на Обслуживании*",G:G)-S17 -> 430.9 | T16: 22-03-26 14:19 | U16: =(I16-T16)*24 -> 2.45 | V16: =IF(U16<=1,0,U16-U16) -> 0
A17: ИТОГО по лок-ву в хоз.движении | R17: НР | S17: =SUMIF(A:A,"*на Обслуживании по вине Исполнителя*",G:G) -> 113.63333 | U17: =SUM(U14:U16)*2 -> 55.266667 | V17: =SUM(V14:V16)*2 -> 33.333333
A18: ИТОГО по лок-ву в обычном движении | E18: =Пробеги!E20+Пробеги!E21 -> 38796 | F18: =E18 -> 38796 | G18: 0 | H18: =F18 -> 38796 | R18: Рекламация | S18: =SUMIF(A:A,"*на Обслуживании по рекламационным ремонтам*",G:G) -> 0
A19: 1 | B19: 2ЭС7 | C19: 002 | D19: 2 | I19: 04-03-26 10:50 | J19: =RIGHT(I19,5) -> 10:50 | K19: №486 | L19: ТО-2 | M19: 04-03-26 12:54 | N19: =RIGHT(M19,5) -> 12:54 | O19: =K19 -> №486 | P19: =(M19-I19)*24 -> 2.0666667 | Q19: =P19*2 -> 4.1333333 | R19: Адм.изд. | S19: =SUMIF(A:A,"*административных издержек*",G:G) -> 338.5 | T19: 04-03-26 06:26 | U19: =(I19-T19)*24 -> 4.4 | V19: =IF(U19<=1,0,U19-U19) -> 0
A20: 2 | B20: 2ЭС7 | C20: 002 | D20: 2 | I20: 25-03-26 00:47 | J20: =RIGHT(I20,5) -> 00:47 | K20: №636 | L20: ТО-2 | M20: 25-03-26 02:48 | N20: =RIGHT(M20,5) -> 02:48 | O20: =K20 -> №636 | P20: =(M20-I20)*24 -> 2.0166667 | Q20: =P20*2 -> 4.0333333 | R20: План КГЭ | S20: =#REF! -> #REF! | T20: 24-03-26 18:44 | U20: =(I20-T20)*24 -> 6.05 | V20: =IF(U20<=1,0,U20-U20) -> 0
A21: ИТОГО по лок-ву в хоз.движении | R21: Адм.изд. РЖД раб | S21: =U62-V62+Z95+Z93+Z96+Z97+Z98+Z99+Z100+Z101+Z102 -> 59.5 | U21: =SUM(U19:U20)*2 -> 20.9 | V21: =SUM(V19:V20)*2 -> 0
A22: ИТОГО по лок-ву в обычном движении | E22: =Пробеги!E22+Пробеги!E23 -> 43322 | F22: =E22 -> 43322 | G22: 0 | H22: =F22 -> 43322 | R22: НР РЖД | S22: =Z78+Z79+Z80+Z81 -> 17.666667
A23: 1 | B23: 2ЭС7 | C23: 003 | D23: 2 | I23: 03-03-26 09:49 | J23: =RIGHT(I23,5) -> 09:49 | K23: №5 | L23: ТО-4 | M23: 05-03-26 18:11 | N23: =RIGHT(M23,5) -> 18:11 | O23: =K23 -> №5 | P23: =(M23-I23)*24 -> 56.366667 | Q23: =P23*2 -> 112.73333 | R23: Адм.изд. РЖД | S23: =Z112+Z113 -> 0 | T23: 01-03-26 22:26 | U23: =(I23-T23)*24 -> 35.383333 | V23: =U23-U23 -> 0
A24: 2 | B24: 2ЭС7 | C24: 003 | D24: 2 | I24: 16-03-26 03:10 | J24: =RIGHT(I24,5) -> 03:10 | K24: №570 | L24: ТО-2 | M24: 16-03-26 05:06 | N24: =RIGHT(M24,5) -> 05:06 | O24: =K24 -> №570 | P24: =(M24-I24)*24 -> 1.9333333 | Q24: =P24*2 -> 3.8666667 | T24: 16-03-26 02:17 | U24: =(I24-T24)*24 -> 0.88333333 | V24: =IF(U24<=1,0,U24-U24) -> 0
A25: Итого часов в хоз.движении | U25: =SUM(U23:U24)*2 -> 72.533333 | V25: =SUM(V23:V24)*2 -> 0
A26: Итого часов в обычном движении | E26: =Пробеги!E24+Пробеги!E25 -> 37596 | F26: =E26 -> 37596 | G26: 0 | H26: =F26 -> 37596
A27: 1 | B27: 2ЭС7 | C27: 004 | D27: 2 | I27: 07-03-26 11:10 | J27: =RIGHT(I27,5) -> 11:10 | K27: №216 | L27: НР | M27: 09-03-26 11:21 | N27: =RIGHT(M27,5) -> 11:21 | O27: =K27 -> №216 | P27: =(M27-I27)*24 -> 48.183333 | Q27: =P27*2 -> 96.366667 | T27: 07-03-26 11:10 | U27: =(I27-T27)*24 -> 0 | V27: =U27 -> 0
A28: 2 | B28: 2ЭС7 | C28: 004 | D28: 2 | I28: 18-03-26 23:07 | J28: =RIGHT(I28,5) -> 23:07 | K28: №585 | L28: ТО-2 | M28: 19-03-26 01:04 | N28: =RIGHT(M28,5) -> 01:04 | O28: =K28 -> №585 | P28: =(M28-I28)*24 -> 1.95 | Q28: =P28*2 -> 3.9 | T28: 18-03-26 21:29 | U28: =(I28-T28)*24 -> 1.6333333 | V28: =IF(U28<=1,0,U28-U28) -> 0
A29: Итого часов в хоз.движении | U29: =SUM(U27:U28)*2 -> 3.2666667 | V29: =SUM(V27:V28)*2 -> 0
A30: Итого часов в обычном движении | E30: =Пробеги!E26+Пробеги!E27 -> 40694 | F30: =E30 -> 40694 | G30: 0 | H30: =F30 -> 40694
A31: 1 | B31: 2ЭС7 | C31: 005 | D31: 2 | I31: 01-03-26 05:12 | J31: =RIGHT(I31,5) -> 05:12 | K31: №466 | L31: ТО-2 | M31: 01-03-26 07:17 | N31: =RIGHT(M31,5) -> 07:17 | O31: =K31 -> №466 | P31: =(M31-I31)*24 -> 2.0833333 | Q31: =P31*2 -> 4.1666667 | T31: 28-02-26 19:13 | U31: =(I31-T31)*24 -> 9.9833333 | V31: =IF(U31<=1,0,U31-U31) -> 0
A32: 2 | B32: 2ЭС7 | C32: 005 | D32: 2 | I32: 24-03-26 02:04 | J32: =RIGHT(I32,5) -> 02:04 | K32: №628 | L32: ТО-2 | M32: 24-03-26 04:23 | N32: =RIGHT(M32,5) -> 04:23 | O32: =K32 -> №628 | P32: =(M32-I32)*24 -> 2.3166667 | Q32: =P32*2 -> 4.6333333 | T32: 24-03-26 02:02 | U32: =(I32-T32)*24 -> 0.033333333 | V32: =IF(U32<=1,0,U32-U32) -> 0
A33: Итого часов в хоз.движении
A34: Итого часов в обычном движении | E34: =Пробеги!E28+Пробеги!E29 -> 39044 | F34: =E34 -> 39044 | G34: 0 | H34: =F34 -> 39044 | U34: =SUM(U31:U33)*2 -> 20.033333 | V34: =SUM(V31:V33)*2 -> 0
A35: 1 | B35: 2ЭС7 | C35: 006 | D35: 2 | I35: 18-03-26 16:44 | J35: =RIGHT(I35,5) -> 16:44 | K35: №583 | L35: ТО-2 | M35: 18-03-26 19:13 | N35: =RIGHT(M35,5) -> 19:13 | O35: =K35 -> №583 | P35: =(M35-I35)*24 -> 2.4833333 | Q35: =P35*2 -> 4.9666667 | T35: 18-03-26 09:33 | U35: =(I35-T35)*24 -> 7.1833333 | V35: =IF(U35<=1,0,U35-U35) -> 0
A36: 2 | B36: 2ЭС7 | C36: 006 | D36: 2 | I36: 18-03-26 19:14 | J36: =RIGHT(I36,5) -> 19:14 | K36: №246 | L36: НР | M36: 23-03-26 19:25 | N36: =RIGHT(M36,5) -> 19:25 | O36: =K36 -> №246 | P36: =(M36-I36)*24 -> 120.18333 | Q36: =P36*2 -> 240.36667 | T36: 18-03-26 19:14 | U36: =(I36-T36)*24 -> 0 | V36: 0
A37: Итого часов в хоз.движении
A38: Итого часов в обычном движении | E38: =Пробеги!E30+Пробеги!E31 -> 31592 | F38: =E38 -> 31592 | G38: 0 | H38: =F38 -> 31592 | U38: =SUM(U35:U37)*2 -> 14.366667 | V38: =SUM(V35:V37)*2 -> 0
A39: 1 | B39: 2ЭС7 | C39: 007 | D39: 2 | I39: 18-03-26 00:30 | J39: =RIGHT(I39,5) -> 00:30 | K39: №580 | L39: ТО-2 | M39: 18-03-26 02:41 | N39: =RIGHT(M39,5) -> 02:41 | O39: =K39 -> №580 | P39: =(M39-I39)*24 -> 2.1833333 | Q39: =P39*2 -> 4.3666667 | T39: 17-03-26 20:31 | U39: =(I39-T39)*24 -> 3.9833333 | V39: =IF(U39<=1,0,U39-U39) -> 0
A40: 2 | B40: 2ЭС7 | C40: 007 | D40: 2 | I40: 28-03-26 15:11 | J40: =RIGHT(I40,5) -> 15:11 | K40: №8 | L40: ТО-4 | M40: 28-03-26 22:11 | N40: =RIGHT(M40,5) -> 22:11 | O40: =K40 -> №8 | P40: =(M40-I40)*24 -> 7 | Q40: =P40*2 -> 14 | T40: 27-03-26 18:26 | U40: =(I40-T40)*24 -> 20.75 | V40: =IF(U40<=1,0,U40-U40) -> 0
A41: Итого часов в хоз.движении
A42: Итого часов в обычном движении | E42: =Пробеги!E32+Пробеги!E33 -> 37894 | F42: =E42 -> 37894 | G42: 0 | H42: =F42 -> 37894 | U42: =SUM(U39:U41)*2 -> 49.466667 | V42: =SUM(V39:V41)*2 -> 0
A43: 1 | B43: 2ЭС7 | C43: 008 | D43: 2 | I43: 01-03-26 11:26 | J43: =RIGHT(I43,5) -> 11:26 | K43: №468 | L43: ТО-2 | M43: 01-03-26 13:28 | N43: =RIGHT(M43,5) -> 13:28 | O43: =K43 -> №468 | P43: =(M43-I43)*24 -> 2.0333333 | Q43: =P43*2 -> 4.0666667 | T43: 01-03-26 07:44 | U43: =(I43-T43)*24 -> 3.7 | V43: =IF(U43<=1,0,U43-U43) -> 0
A44: 2 | B44: 2ЭС7 | C44: 008 | D44: 2 | I44: 21-03-26 21:04 | J44: =RIGHT(I44,5) -> 21:04 | K44: №609 | L44: ТО-2 | M44: 21-03-26 23:34 | N44: =RIGHT(M44,5) -> 23:34 | O44: =K44 -> №609 | P44: =(M44-I44)*24 -> 2.5 | Q44: =P44*2 -> 5 | T44: 21-03-26 18:12 | U44: =(I44-T44)*24 -> 2.8666667 | V44: =IF(U44<=1,0,U44-U44) -> 0
A45: 3 | B45: 2ЭС7 | C45: 008 | D45: 2 | I45: 21-03-26 23:34 | J45: =RIGHT(I45,5) -> 23:34 | K45: №255 | L45: НР | M45: 26-03-26 12:58 | N45: =RIGHT(M45,5) -> 12:58 | O45: =K45 -> №255 | P45: =(M45-I45)*24 -> 109.4 | Q45: =P45*2 -> 218.8 | T45: 21-03-26 23:34 | U45: =(I45-T45)*24 -> 0 | V45: 0
A46: Итого часов в хоз.движении
A47: Итого часов в обычном движении | E47: =Пробеги!E34+Пробеги!E35 -> 35170 | F47: =E47 -> 35170 | G47: 0 | H47: =F47 -> 35170 | U47: =SUM(U43:U46)*2 -> 13.133333 | V47: =SUM(V43:V46)*2 -> 0
O49: Страница 1 из 2
A50: 1 | B50: 2ЭС7 | C50: 009 | D50: 2 | I50: 02-03-26 09:41 | J50: =RIGHT(I50,5) -> 09:41 | K50: №25 | L50: ТР-1 | M50: 04-03-26 15:31 | N50: =RIGHT(M50,5) -> 15:31 | O50: =K50 -> №25 | P50: =(M50-I50)*24 -> 53.833333 | Q50: =P50*2 -> 107.66667 | T50: 28-02-26 16:40 | U50: =(I50-T50)*24 -> 41.016667 | V50: =IF(U50<=1,0,U50-U50) -> 0
A51: 2 | B51: 2ЭС7 | C51: 009 | D51: 2 | I51: 23-03-26 12:48 | J51: =RIGHT(I51,5) -> 12:48 | K51: №621 | L51: ТО-2 | M51: 23-03-26 14:49 | N51: =RIGHT(M51,5) -> 14:49 | O51: =K51 -> №621 | P51: =(M51-I51)*24 -> 2.0166667 | Q51: =P51*2 -> 4.0333333 | T51: 23-03-26 09:57 | U51: =(I51-T51)*24 -> 2.85 | V51: =IF(U51<=1,0,U51-U51) -> 0
A52: Итого часов в хоз.движении | U52: =SUM(U50:U51)*2 -> 87.733333 | V52: =SUM(V50:V51)*2 -> 0
...

Sheet Пробеги
A1: Отчёт по пробегам секций локомотивов, времени пребывания локомотивов в эксплуатируемом и неэксплуатируемом парках
A2: Дата и время выдачи справки: 2026-04-01 05.19
A3: Начало интервала: 2026-02-28 18.00.00
A4: Окончание интервала: 2026-03-31 18.00.00
A5: Дирекция тяги приписки: Октябрьская
A6: Депо приписки: ТЧЭ-22 БАБАЕВО
A7: Вид тяги: электровозы
A8: Род службы ТПС: все
A9: Группа серий ТПС: все
A10: Серия локомотивов: 2ЭС7
A11: Номер секции: все
A12: Признак секции: все
A14: Отчёт по пробегам локомотивов
A15: Дирекция | B15: Депо | C15: Серия | D15: Номер | E15: Фактический | G15: Фактическое время в | K15: Фактическое время в
A16: тяги | B16: приписки | C16: локомотива | D16: секции | E16: пробег | G16: эксплуатируемом парке, ч | K16: неэксплуатируемом парке, ч
A17: приписки | B17: локомотива | E17: км | F17: ч | G17: Итого | H17: В том числе в | I17: В том числе в | J17: В том числе в ожидании ТО-2, на ТО-2 и экипировке | K17: Итого | L17: В том числе на | M17: В том числе на
H18: рабочем парке | I18: ожидании работы | L18: плановых ТО, ТР | M18: неплановых ремонтах
A19: 1 | B19: 2 | C19: 3 | D19: 4 | E19: 5 | F19: 6 | G19: 7 | H19: 8 | I19: 9 | J19: 10 | K19: 11 | L19: 12 | M19: 13
A20: Октябрьская | B20: ТЧЭ-22 БАБАЕВО | C20: 2ЭС7 | D20: 0001 A | E20: 19398 | F20: 700 | G20: 700 | H20: 519 | I20: 62 | J20: 20 | K20: 44 | L20: 0 | M20: 27
A21: Октябрьская | B21: ТЧЭ-22 БАБАЕВО | C21: 2ЭС7 | D21: 0001 Б | E21: 19398 | F21: 700 | G21: 700 | H21: 519 | I21: 62 | J21: 20 | K21: 44 | L21: 0 | M21: 27
A22: Октябрьская | B22: ТЧЭ-22 БАБАЕВО | C22: 2ЭС7 | D22: 0002 A | E22: 21661 | F22: 744 | G22: 744 | H22: 586 | I22: 54 | J22: 19 | K22: 0 | L22: 0 | M22: 0
A23: Октябрьская | B23: ТЧЭ-22 БАБАЕВО | C23: 2ЭС7 | D23: 0002 Б | E23: 21661 | F23: 744 | G23: 744 | H23: 586 | I23: 54 | J23: 19 | K23: 0 | L23: 0 | M23: 0
A24: Октябрьская | B24: ТЧЭ-22 БАБАЕВО | C24: 2ЭС7 | D24: 0003 A | E24: 18798 | F24: 652 | G24: 652 | H24: 518 | I24: 59 | J24: 9 | K24: 92 | L24: 76 | M24: 0
A25: Октябрьская | B25: ТЧЭ-22 БАБАЕВО | C25: 2ЭС7 | D25: 0003 Б | E25: 18798 | F25: 652 | G25: 652 | H25: 518 | I25: 59 | J25: 9 | K25: 92 | L25: 76 | M25: 0
A26: Октябрьская | B26: ТЧЭ-22 БАБАЕВО | C26: 2ЭС7 | D26: 0004 A | E26: 20347 | F26: 691 | G26: 691 | H26: 537 | I26: 49 | J26: 21 | K26: 53 | L26: 0 | M26: 53
A27: Октябрьская | B27: ТЧЭ-22 БАБАЕВО | C27: 2ЭС7 | D27: 0004 Б | E27: 20347 | F27: 691 | G27: 691 | H27: 537 | I27: 49 | J27: 21 | K27: 53 | L27: 0 | M27: 53
A28: Октябрьская | B28: ТЧЭ-22 БАБАЕВО | C28: 2ЭС7 | D28: 0005 A | E28: 19522 | F28: 662 | G28: 662 | H28: 512 | I28: 56 | J28: 16 | K28: 82 | L28: 0 | M28: 9
A29: Октябрьская | B29: ТЧЭ-22 БАБАЕВО | C29: 2ЭС7 | D29: 0005 Б | E29: 19522 | F29: 662 | G29: 662 | H29: 512 | I29: 56 | J29: 16 | K29: 82 | L29: 0 | M29: 9
A30: Октябрьская | B30: ТЧЭ-22 БАБАЕВО | C30: 2ЭС7 | D30: 0006 A | E30: 15796 | F30: 624 | G30: 624 | H30: 459 | I30: 78 | J30: 17 | K30: 120 | L30: 0 | M30: 120
A31: Октябрьская | B31: ТЧЭ-22 БАБАЕВО | C31: 2ЭС7 | D31: 0006 Б | E31: 15796 | F31: 624 | G31: 624 | H31: 459 | I31: 78 | J31: 17 | K31: 120 | L31: 0 | M31: 120
... A45: Октябрьская | B45: ТЧЭ-22 БАБАЕВО | C45: 2ЭС7 | D45: 0013 Б | E45: 18179 | F45: 650 | G45: 650 | H45: 485 | I45: 60 | J45: 25 | K45: 95 | L45: 21 | M45: 74
A46: Итого: | E46: 492026 | F46: 17502 | G46: 17502 | H46: 13304 | I46: 1618 | J46: 464 | K46: 1844 | L46: 516 | M46: 1044
E47: =E46/31/26 -> 610.45409
