Workbook

Sheet СТА за март 2026
A1: Сводный технический Акт выполненных работ и оказанных услуг
A10: № п/п | B10: Номер Локомотива | C10: Фактический пробег локомотива за период * | D10: Пробег всех секций локомотива подлежащий оплате * | E10: Количество часов нахождения локомотива в эксплуатации** | F10: Дата постановки Локомотива в ремонт | G10: Время постановки Локомотива в ремонт | H10: № Акта приемки Локомотива в ремонт | I10: Вид ремонта | J10: Дата выхода Локомотива из ремонта | K10: Время выхода Локомотива из ремонта | L10: № Акта приемки Локомотива из ремонта | M10: Количество часов нахождения Локомотива в ремонте* | P10: Дата постановки в ОЖ. ТО-2, ОЖ. ТО-2 с экипировкой,ож ТР, ож НЕПЛ РЕМ | Q10: Время в ОЖ. | R10: Время в ОЖ. За вычетом 1 часа в ИСПРАВНОМ состоянии
A11: 1 | B11: 1539 | F11: 08-03-26 03:09 | G11: =RIGHT(F11,5) -> 03:09 | H11: №519 | I11: ТО-2 | J11: 08-03-26 04:09 | K11: =RIGHT(J11,5) -> 04:09 | L11: =H11 -> №519 | M11: =(J11-F11)*24 -> 1 | N11: Эксплуатация | O11: =SUMIF(A:A,"*в работоспособном состоянии*",E:E) -> 48108.733 | P11: 07-03-26 23:46 | Q11: =(F11-P11)*24 -> 3.3833333 | R11: =Q11-1 -> 2.3833333
A12: 2 | B12: 1539 | F12: 15-03-26 12:44 | G12: =RIGHT(F12,5) -> 12:44 | H12: №566 | I12: ТО-2 | J12: 15-03-26 13:53 | K12: =RIGHT(J12,5) -> 13:53 | L12: =H12 -> №566 | M12: =(J12-F12)*24 -> 1.15 | N12: Пробег | O12: =SUMIF(A:A,"*ВСЕГО*",D:D) -> 1764236 | P12: 15-03-26 09:41 | Q12: =(F12-P12)*24 -> 3.05 | R12: =Q12-1 -> 2.05
A13: 3 | B13: 1539 | F13: 23-03-26 22:33 | G13: =RIGHT(F13,5) -> 22:33 | H13: №626 | I13: ТО-2 | J13: 23-03-26 23:49 | K13: =RIGHT(J13,5) -> 23:49 | L13: =H13 -> №626 | M13: =(J13-F13)*24 -> 1.2666667 | N13: Обслуживание | O13: =SUMIF(A:A,"*в Обслуживании:*",E:E) -> 689.63333 | P13: 23-03-26 18:44 | Q13: =(F13-P13)*24 -> 3.8166667 | R13: =Q13-1 -> 2.8166667
A14: 4 | B14: 1539 | F14: 31-03-26 04:10 | G14: =RIGHT(F14,5) -> 04:10 | H14: №682 | I14: ТО-2 | J14: 31-03-26 05:27 | K14: =RIGHT(J14,5) -> 05:27 | L14: =H14 -> №682 | M14: =(J14-F14)*24 -> 1.2833333 | N14: НР | P14: 30-03-26 18:54 | Q14: =(F14-P14)*24 -> 9.2666667 | R14: =Q14-1 -> 8.2666667
A15: ИТОГО по лок-ву | C15: =Пробеги!E20 -> 13892 | D15: =C15*2 -> 27784 | E15: =DAY(EOMONTH($S$427,0))*24-M15-R15 -> 723.78333 | M15: =SUM(M11:M14) -> 4.7 | N15: Рекламация | O15: =SUMIF(A:A,"*в Обслуживании гарантийном*",E:E) -> 50.383333 | Q15: =SUM(Q11:Q14) -> 19.516667 | R15: =SUM(R11:R14) -> 15.516667
A16: 1 | B16: 1540 | F16: 02-03-26 09:24 | G16: =RIGHT(F16,5) -> 09:24 | H16: №476 | I16: ТО-2 | J16: 02-03-26 10:29 | K16: =RIGHT(J16,5) -> 10:29 | L16: =H16 -> №476 | M16: =(J16-F16)*24 -> 1.0833333 | N16: Адм.изд. | O16: =SUMIF(A:A,"*в ожидании ТО-2*",E:E)+V52+V51 -> 745.93333 | P16: 02-03-26 05:59 | Q16: =(F16-P16)*24 -> 3.4166667 | R16: =Q16-1 -> 2.4166667
A17: 2 | B17: 1540 | F17: 09-03-26 11:33 | G17: =RIGHT(F17,5) -> 11:33 | H17: №527 | I17: ТО-2 | J17: 09-03-26 13:14 | K17: =RIGHT(J17,5) -> 13:14 | L17: =H17 -> №527 | M17: =(J17-F17)*24 -> 1.6833333 | N17: План КГЭ | O17: =0.95 -> 0.95 | P17: 09-03-26 06:11 | Q17: =(F17-P17)*24 -> 5.3666667 | R17: =Q17-1 -> 4.3666667
A18: 3 | B18: 1540 | F18: 09-03-26 13:15 | G18: =RIGHT(F18,5) -> 13:15 | H18: №220 | I18: НР | J18: 09-03-26 18:40 | K18: =RIGHT(J18,5) -> 18:40 | L18: =H18 -> №220 | M18: =(J18-F18)*24 -> 5.4166667 | N18: Адм.изд. РЖД раб | P18: 09-03-26 13:15 | Q18: =(F18-P18)*24 -> 0 | R18: =Q18 -> 0
A19: 4 | B19: 1540 | F19: 15-03-26 10:17 | G19: =RIGHT(F19,5) -> 10:17 | H19: №33 | I19: ТР-1 | J19: 15-03-26 20:28 | K19: =RIGHT(J19,5) -> 20:28 | L19: =H19 -> №33 | M19: =(J19-F19)*24 -> 10.183333 | N19: НР РЖД | O19: =E300 -> 0 | P19: 13-03-26 05:30 | Q19: 11.8 | R19: =Q19-Q19 -> 0
A20: 5 | B20: 1540 | F20: 25-03-26 03:30 | G20: =RIGHT(F20,5) -> 03:30 | H20: №637 | I20: ТО-2 | J20: 25-03-26 04:47 | K20: =RIGHT(J20,5) -> 04:47 | L20: =H20 -> №637 | M20: =(J20-F20)*24 -> 1.2833333 | N20: Адм.изд. РЖД | O20: =X322 -> 0 | P20: 24-03-26 21:52 | Q20: =(F20-P20)*24 -> 5.6333333 | R20: =Q20-1 -> 4.6333333
A21: ИТОГО по лок-ву | C21: =Пробеги!E22 -> 12849 | D21: =C21*2 -> 25698 | E21: =DAY(EOMONTH($S$427,0))*24-M21-R21 -> 712.93333 | M21: =SUM(M16:M20) -> 19.65 | Q21: =SUM(Q16:Q20) -> 26.216667 | R21: =SUM(R16:R20) -> 11.416667
A22: 1 | B22: 1541 | F22: 07-03-26 07:42 | G22: =RIGHT(F22,5) -> 07:42 | H22: №28 | I22: ТР-1 | J22: 07-03-26 19:30 | K22: =RIGHT(J22,5) -> 19:30 | L22: =H22 -> №28 | M22: =(J22-F22)*24 -> 11.8 | P22: 05-03-26 14:26 | Q22: 11.8 | R22: =Q22-Q22 -> 0
A23: 2 | B23: 1541 | F23: 16-03-26 16:05 | G23: =RIGHT(F23,5) -> 16:05 | H23: №576 | I23: ТО-2 | J23: 16-03-26 17:13 | K23: =RIGHT(J23,5) -> 17:13 | L23: =H23 -> №576 | M23: =(J23-F23)*24 -> 1.1333333 | P23: 14-03-26 09:38 | Q23: =(F23-P23)*24 -> 54.45 | R23: 0
A24: 3 | B24: 1541 | F24: 24-03-26 04:05 | G24: =RIGHT(F24,5) -> 04:05 | H24: №629 | I24: ТО-2 | J24: 24-03-26 05:10 | K24: =RIGHT(J24,5) -> 05:10 | L24: =H24 -> №629 | M24: =(J24-F24)*24 -> 1.0833333 | P24: 24-03-26 00:28 | Q24: =(F24-P24)*24 -> 3.6166667 | R24: =Q24-1 -> 2.6166667
A25: 4 | B25: 1541 | F25: 31-03-26 18:13 | G25: =RIGHT(F25,5) -> 18:13 | H25: №276 | I25: НР | J25: 31-03-26 20:15 | K25: =RIGHT(J25,5) -> 20:15 | L25: =H25 -> №276 | M25: =(J25-F25)*24 -> 2.0333333 | P25: 31-03-26 07:45 | Q25: =(F25-P25)*24 -> 10.466667 | R25: 0
A26: ИТОГО по лок-ву | C26: =Пробеги!E24 -> 11384 | D26: =C26*2 -> 22768 | E26: =DAY(EOMONTH($S$427,0))*24-M26-R26 -> 725.33333 | M26: =SUM(M22:M25) -> 16.05 | Q26: =SUM(Q22:Q25) -> 80.333333 | R26: =SUM(R22:R25) -> 2.6166667
A27: 1 | B27: 1542 | F27: 05-03-26 14:13 | G27: =RIGHT(F27,5) -> 14:13 | H27: №27 | I27: ТР-1 | J27: 06-03-26 21:54 | K27: =RIGHT(J27,5) -> 21:54 | L27: =H27 -> №27 | M27: =(J27-F27)*24 -> 31.683333 | P27: 05-03-26 02:25 | Q27: =(F27-P27)*24 -> 11.8 | R27: =Q27-Q27 -> 0
A28: 2 | B28: 1542 | F28: 13-03-26 12:01 | G28: =RIGHT(F28,5) -> 12:01 | H28: №553 | I28: ТО-2 | J28: 13-03-26 13:14 | K28: =RIGHT(J28,5) -> 13:14 | L28: =H28 -> №553 | M28: =(J28-F28)*24 -> 1.2166667 | P28: 13-03-26 08:31 | Q28: =(F28-P28)*24 -> 3.5 | R28: =Q28-1 -> 2.5
A29: 3 | B29: 1542 | F29: 20-03-26 23:31 | G29: =RIGHT(F29,5) -> 23:31 | H29: №602 | I29: ТО-2 | J29: 21-03-26 00:40 | K29: =RIGHT(J29,5) -> 00:40 | L29: =H29 -> №602 | M29: =(J29-F29)*24 -> 1.15 | P29: 20-03-26 22:16 | Q29: =(F29-P29)*24 -> 1.25 | R29: =Q29-1 -> 0.25
A30: 4 | B30: 1542 | F30: 27-03-26 22:48 | G30: =RIGHT(F30,5) -> 22:48 | H30: №660 | I30: ТО-2 | J30: 27-03-26 23:58 | K30: =RIGHT(J30,5) -> 23:58 | L30: =H30 -> №660 | M30: =(J30-F30)*24 -> 1.1666667 | P30: 27-03-26 16:25 | Q30: =(F30-P30)*24 -> 6.3833333 | R30: =Q30-1 -> 5.3833333
A31: ИТОГО по лок-ву | C31: =Пробеги!E26 -> 13461 | D31: =C31*2 -> 26922 | E31: =DAY(EOMONTH($S$427,0))*24-M31-R31 -> 700.65 | M31: =SUM(M27:M30) -> 35.216667 | Q31: =SUM(Q27:Q30) -> 22.933333 | R31: =SUM(R27:R30) -> 8.1333333
A32: 1 | B32: 1543 | F32: 04-03-26 16:30 | G32: =RIGHT(F32,5) -> 16:30 | H32: №489 | I32: ТО-2 | J32: 04-03-26 17:54 | K32: =RIGHT(J32,5) -> 17:54 | L32: =H32 -> №489 | M32: =(J32-F32)*24 -> 1.4 | P32: 04-03-26 10:09 | Q32: =(F32-P32)*24 -> 6.35 | R32: =Q32-1 -> 5.35
A33: 2 | B33: 1543 | F33: 12-03-26 03:24 | G33: =RIGHT(F33,5) -> 03:24 | H33: №545 | I33: ТО-2 | J33: 12-03-26 04:27 | K33: =RIGHT(J33,5) -> 04:27 | L33: =H33 -> №545 | M33: =(J33-F33)*24 -> 1.05 | P33: 11-03-26 23:36 | Q33: =(F33-P33)*24 -> 3.8 | R33: =Q33-1 -> 2.8
A34: 3 | B34: 1543 | F34: 19-03-26 22:05 | G34: =RIGHT(F34,5) -> 22:05 | H34: №597 | I34: ТО-2 | J34: 19-03-26 23:05 | K34: =RIGHT(J34,5) -> 23:05 | L34: =H34 -> №597 | M34: =(J34-F34)*24 -> 1 | P34: 19-03-26 16:36 | Q34: =(F34-P34)*24 -> 5.4833333 | R34: =Q34-1 -> 4.4833333
A35: 4 | B35: 1543 | F35: 27-03-26 20:13 | G35: =RIGHT(F35,5) -> 20:13 | H35: №658 | I35: ТО-2 | J35: 27-03-26 21:22 | K35: =RIGHT(J35,5) -> 21:22 | L35: =H35 -> №658 | M35: =(J35-F35)*24 -> 1.15 | P35: 27-03-26 13:03 | Q35: =(F35-P35)*24 -> 7.1666667 | R35: =Q35-1 -> 6.1666667
A36: ИТОГО по лок-ву | C36: =Пробеги!E28 -> 13668 | D36: =C36*2 -> 27336 | E36: =DAY(EOMONTH($S$427,0))*24-M36-R36 -> 720.6 | M36: =SUM(M32:M35) -> 4.6 | Q36: =SUM(Q32:Q35) -> 22.8 | R36: =SUM(R32:R35) -> 18.8
A37: 1 | B37: 1544 | F37: 07-03-26 21:01 | G37: =RIGHT(F37,5) -> 21:01 | H37: №517 | I37: ТО-2 | J37: 07-03-26 22:02 | K37: =RIGHT(J37,5) -> 22:02 | L37: =H37 -> №517 | M37: =(J37-F37)*24 -> 1.0166667 | P37: 07-03-26 16:42 | Q37: =(F37-P37)*24 -> 4.3166667 | R37: =Q37-1 -> 3.3166667
A38: 2 | B38: 1544 | F38: 12-03-26 11:46 | G38: =RIGHT(F38,5) -> 11:46 | H38: №7 | I38: ТО-4 | J38: 14-03-26 18:58 | K38: =RIGHT(J38,5) -> 18:58 | L38: =H38 -> №7 | M38: =(J38-F38)*24 -> 55.2 | P38: 09-03-26 06:19 | Q38: 11.8 | R38: =Q38-Q38 -> 0
A39: 3 | B39: 1544 | F39: 23-03-26 03:04 | G39: =RIGHT(F39,5) -> 03:04 | H39: №618 | I39: ТО-2 | J39: 23-03-26 04:14 | K39: =RIGHT(J39,5) -> 04:14 | L39: =H39 -> №618 | M39: =(J39-F39)*24 -> 1.1666667 | P39: 22-03-26 14:04 | Q39: =(F39-P39)*24 -> 13 | R39: =Q39-1 -> 12
A40: ИТОГО по лок-ву | C40: =Пробеги!E30 -> 11468 | D40: =C40*2 -> 22936 | E40: =DAY(EOMONTH($S$427,0))*24-M40-R40 -> 671.3 | M40: =SUM(M37:M39) -> 57.383333 | Q40: =SUM(Q37:Q39) -> 29.116667 | R40: =SUM(R37:R39) -> 15.316667
L42: Страница 1 из 8
A43: 1 | B43: 1545 | F43: 06-03-26 03:02 | G43: =RIGHT(F43,5) -> 03:02 | H43: №208 | I43: НР | J43: 06-03-26 16:28 | K43: =RIGHT(J43,5) -> 16:28 | L43: =H43 -> №208 | M43: =(J43-F43)*24 -> 13.433333 | P43: 05-03-26 19:00 | Q43: =(F43-P43)*24 -> 8.0333333 | R43: =Q43 -> 8.0333333
A44: 2 | B44: 1545 | F44: 11-03-26 18:39 | G44: =RIGHT(F44,5) -> 18:39 | H44: №542 | I44: ТО-2 | J44: 11-03-26 19:52 | K44: =RIGHT(J44,5) -> 19:52 | L44: =H44 -> №542 | M44: =(J44-F44)*24 -> 1.2166667 | P44: 11-03-26 18:23 | Q44: =(F44-P44)*24 -> 0.26666667 | R44: =Q44-Q44 -> 0
A45: 3 | B45: 1545 | F45: 21-03-26 11:06 | G45: =RIGHT(F45,5) -> 11:06 | H45: №605 | I45: ТО-2 | J45: 21-03-26 12:38 | K45: =RIGHT(J45,5) -> 12:38 | L45: =H45 -> №605 | M45: =(J45-F45)*24 -> 1.5333333 | P45: 21-03-26 10:39 | Q45: =(F45-P45)*24 -> 0.45 | R45: =Q45-Q45 -> 0
A46: ИТОГО по лок-ву | C46: =Пробеги!E32 -> 13596 | D46: =C46*2 -> 27192 | E46: =DAY(EOMONTH($S$427,0))*24-M46-R46 -> 719.78333 | M46: =SUM(M43:M45) -> 16.183333 | Q46: =SUM(Q43:Q45) -> 8.75 | R46: =SUM(R43:R45) -> 8.0333333
A47: 1 | B47: 1546 | F47: 02-03-26 22:25 | G47: =RIGHT(F47,5) -> 22:25 | H47: №479 | I47: ТО-2 | J47: 02-03-26 23:50 | K47: =RIGHT(J47,5) -> 23:50 | L47: =H47 -> №479 | M47: =(J47-F47)*24 -> 1.4166667 | P47: 02-03-26 20:52 | Q47: =(F47-P47)*24 -> 1.55 | R47: =Q47-1 -> 0.55
A48: 2 | B48: 1546 | F48: 12-03-26 13:51 | G48: =RIGHT(F48,5) -> 13:51 | H48: №547 | I48: ТО-2 | J48: 12-03-26 14:52 | K48: =RIGHT(J48,5) -> 14:52 | L48: =H48 -> №547 | M48: =(J48-F48)*24 -> 1.0166667 | P48: 12-03-26 13:04 | Q48: =(F48-P48)*24 -> 0.78333333 | R48: =Q48-Q48 -> 0
A49: 3 | B49: 1546 | F49: 22-03-26 03:05 | G49: =RIGHT(F49,5) -> 03:05 | H49: №612 | I49: ТО-2 | J49: 22-03-26 04:10 | K49: =RIGHT(J49,5) -> 04:10 | L49: =H49 -> №612 | M49: =(J49-F49)*24 -> 1.0833333 | P49: 22-03-26 02:27 | Q49: =(F49-P49)*24 -> 0.63333333 | R49: =Q49-Q49 -> 0
...

Sheet Бюджет времени
A1: 1539 | B1: 46081.75 | C1: 46112.75 | D1: =(C1-B1)*24 -> 744
A2: 1540 | B2: 46081.75 | C2: 46112.75 | D2: =(C2-B2)*24 -> 744
A3: 1541 | B3: 46081.75 | C3: 46112.75 | D3: =(C3-B3)*24 -> 744
A4: 1542 | B4: 46081.75 | C4: 46112.75 | D4: =(C4-B4)*24 -> 744
A5: 1543 | B5: 46081.75 | C5: 46112.75 | D5: =(C5-B5)*24 -> 744
A6: 1544 | B6: 46081.75 | C6: 46112.75 | D6: =(C6-B6)*24 -> 744
A7: 1545 | B7: 46081.75 | C7: 46112.75 | D7: =(C7-B7)*24 -> 744
A8: 1546 | B8: 46081.75 | C8: 46112.75 | D8: =(C8-B8)*24 -> 744
A9: 1547 | B9: 46081.75 | C9: 46112.75 | D9: =(C9-B9)*24 -> 744
A10: 1548 | B10: 46081.75 | C10: 46112.75 | D10: =(C10-B10)*24 -> 744
A11: 1602 | B11: 46081.75 | C11: 46112.75 | D11: =(C11-B11)*24 -> 744
A12: 1603 | B12: 46081.75 | C12: 46112.75 | D12: =(C12-B12)*24 -> 744
... A77: 1670 | B77: 46105.69 | C77: 46112.75 | D77: =(C77-B77)*24 -> 169.43333
A78: =COUNTA(A1:A77) -> 77 | D78: =SUM(D1:D77) -> 49634.95

Sheet Пробеги
A1: Отчёт по пробегам секций локомотивов, времени пребывания локомотивов в эксплуатируемом и неэксплуатируемом парках
A2: Дата и время выдачи справки: 2026-04-01 05.06
A3: Начало интервала: 2026-02-28 18.00.00
A4: Окончание интервала: 2026-03-31 18.00.00
A5: Дирекция тяги приписки: Октябрьская
A6: Депо приписки: ТЧЭ-21 ВОЛХОВСТРОЙ
A7: Вид тяги: электровозы
A8: Род службы ТПС: все
A9: Группа серий ТПС: все
A10: Серия локомотивов: 2ЭС6
A11: Номер секции: все
A12: Признак секции: все
A14: Отчёт по пробегам локомотивов
A15: Дирекция | B15: Депо | C15: Серия | D15: Номер | E15: Фактический | G15: Фактическое время в | K15: Фактическое время в
A16: тяги | B16: приписки | C16: локомотива | D16: секции | E16: пробег | G16: эксплуатируемом парке, ч | K16: неэксплуатируемом парке, ч
A17: приписки | B17: локомотива | E17: км | F17: ч | G17: Итого | H17: В том числе в | I17: В том числе в | J17: В том числе в ожидании ТО-2, на ТО-2 и экипировке | K17: Итого | L17: В том числе на | M17: В том числе на
H18: рабочем парке | I18: ожидании работы | L18: плановых ТО, ТР | M18: неплановых ремонтах
A19: 1 | B19: 2 | C19: 3 | D19: 4 | E19: 5 | F19: 6 | G19: 7 | H19: 8 | I19: 9 | J19: 10 | K19: 11 | L19: 12 | M19: 13
A20: Октябрьская | B20: ТЧЭ-21 ВОЛХОВСТРОЙ | C20: 2ЭС6 | D20: 1539 A | E20: 13892 | F20: 744 | G20: 744 | H20: 445 | I20: 56 | J20: 24 | K20: 0 | L20: 0 | M20: 0
A21: Октябрьская | B21: ТЧЭ-21 ВОЛХОВСТРОЙ | C21: 2ЭС6 | D21: 1539 Б | E21: 13892 | F21: 744 | G21: 744 | H21: 445 | I21: 56 | J21: 24 | K21: 0 | L21: 0 | M21: 0
A22: Октябрьская | B22: ТЧЭ-21 ВОЛХОВСТРОЙ | C22: 2ЭС6 | D22: 1540 A | E22: 12849 | F22: 676 | G22: 676 | H22: 434 | I22: 49 | J22: 20 | K22: 69 | L22: 63 | M22: 6
A23: Октябрьская | B23: ТЧЭ-21 ВОЛХОВСТРОЙ | C23: 2ЭС6 | D23: 1540 Б | E23: 12849 | F23: 676 | G23: 676 | H23: 434 | I23: 49 | J23: 20 | K23: 69 | L23: 63 | M23: 6
A24: Октябрьская | B24: ТЧЭ-21 ВОЛХОВСТРОЙ | C24: 2ЭС6 | D24: 1541 A | E24: 11384 | F24: 619 | G24: 619 | H24: 361 | I24: 53 | J24: 60 | K24: 126 | L24: 54 | M24: 10
A25: Октябрьская | B25: ТЧЭ-21 ВОЛХОВСТРОЙ | C25: 2ЭС6 | D25: 1541 Б | E25: 11384 | F25: 619 | G25: 619 | H25: 361 | I25: 53 | J25: 60 | K25: 126 | L25: 54 | M25: 10
A26: Октябрьская | B26: ТЧЭ-21 ВОЛХОВСТРОЙ | C26: 2ЭС6 | D26: 1542 A | E26: 13461 | F26: 700 | G26: 700 | H26: 449 | I26: 94 | J26: 15 | K26: 44 | L26: 44 | M26: 0
A27: Октябрьская | B27: ТЧЭ-21 ВОЛХОВСТРОЙ | C27: 2ЭС6 | D27: 1542 Б | E27: 13461 | F27: 700 | G27: 700 | H27: 449 | I27: 94 | J27: 15 | K27: 44 | L27: 44 | M27: 0
A28: Октябрьская | B28: ТЧЭ-21 ВОЛХОВСТРОЙ | C28: 2ЭС6 | D28: 1543 A | E28: 13668 | F28: 744 | G28: 744 | H28: 469 | I28: 104 | J28: 27 | K28: 0 | L28: 0 | M28: 0
A29: Октябрьская | B29: ТЧЭ-21 ВОЛХОВСТРОЙ | C29: 2ЭС6 | D29: 1543 Б | E29: 13668 | F29: 744 | G29: 744 | H29: 469 | I29: 104 | J29: 27 | K29: 0 | L29: 0 | M29: 0
A30: Октябрьская | B30: ТЧЭ-21 ВОЛХОВСТРОЙ | C30: 2ЭС6 | D30: 1544 A | E30: 11468 | F30: 611 | G30: 611 | H30: 409 | I30: 79 | J30: 29 | K30: 133 | L30: 115 | M30: 0
A31: Октябрьская | B31: ТЧЭ-21 ВОЛХОВСТРОЙ | C31: 2ЭС6 | D31: 1544 Б | E31: 11468 | F31: 611 | G31: 611 | H31: 409 | I31: 79 | J31: 29 | K31: 133 | L31: 115 | M31: 0
... A173: Октябрьская | B173: ТЧЭ-21 ВОЛХОВСТРОЙ | C173: 2ЭС6 | D173: 1670 Б | E173: 1401 | F173: 119 | G173: 119 | H173: 60 | I173: 30 | J173: 9 | K173: 50 | L173: 32 | M173: 0
A174: Итого: | E174: =SUM(E20:E173)/2 -> 882118 | F174: 100256 | G174: 100256 | H174: 64098 | I174: 9438 | J174: 2578 | K174: 6460 | L174: 3446 | M174: 1330
E175: =E174*2 -> 1764236
